Workbook

Sheet SourceLog
A1: Capstone 12 - Source Log: EV chips (SiC/GaN) and India
A2: Legend: edit the yellow cells (Date accessed, Trust level, Used in report, Verification status). Open action (column J) fills in automatically. Add new sources on the next empty row; counts on the Summary sheet update by themselves.
A4: ID | B4: Source | C4: URL | D4: Source type | E4: Used for | F4: Date accessed | G4: Trust level | H4: Used in report | I4: Verification status | J4: Open action | K4: Re-check 24 Oct 2026 | L4: Fix needed in report
A5: 1 | B5: SiC vs Si-IGBT traction inverter paper | C5: https://ph01.tci-thaijo.org/index.php/TNIJournal/article/view/253949 | D5: Research paper | E5: Loss and efficiency gain of SiC inverter | F5: 46313 | G5: High | H5: Yes | I5: Opened and confirmed | J5: =IF(I5="Opened and confirmed","Done",IF(I5="Rejected","Do not cite",IF(I5="Date to confirm","Check page date","Open link and confirm"))) -> Done | K5: SUPPORTED | L5: Say 'simulated' (PLECS simulation, not measured). Don't cite the stray 'over 20%' figure.
A6: 2 | B6: TI: EV traction inverter components | C6: https://www.ti.com/document-viewer/lit/html/SSZTD11/GUID-A8D6BB1F-85F9-43C0-970D-A6B638DA5F7B | D6: Company | E6: Inverter parts; SiC FET adoption | F6: 46313 | G6: Medium (vendor) | H6: Yes | I6: Opened and confirmed | J6: =IF(I6="Opened and confirmed","Done",IF(I6="Rejected","Do not cite",IF(I6="Date to confirm","Check page date","Open link and confirm"))) -> Done | K6: SUPPORTED | L6: Phrase as 'key components' of the inverter.
A7: 3 | B7: NXP BMx7318 fact sheet | C7: https://www.nxp.com/docs/en/fact-sheet/BMx7318FS.pdf | D7: Company | E7: BMS cell-monitor AFE | F7: 46313 | G7: Medium (vendor) | H7: Yes | I7: Opened and confirmed | J7: =IF(I7="Opened and confirmed","Done",IF(I7="Rejected","Do not cite",IF(I7="Date to confirm","Check page date","Open link and confirm"))) -> Done | K7: SUPPORTED | L7: Say 'up to ASIL C' (industrial parts are SIL2). No date on sheet (c) 2026.
A8: 4 | B8: Analog Devices: EV batteries | C8: https://www.analog.com/en/signals/thought-leadership/the-amazing-technology-behind-ev-batteries.html | D8: Company | E8: SoC/SoH in BMS | F8: 46313 | G8: Medium (vendor) | H8: Yes | I8: Opened and confirmed | J8: =IF(I8="Opened and confirmed","Done",IF(I8="Rejected","Do not cite",IF(I8="Date to confirm","Check page date","Open link and confirm"))) -> Done | K8: SUPPORTED | L8: No date on page; c. 2022.
A9: 5 | B9: GaN 6.6 kW on-board charger (PMC) | C9: https://pmc.ncbi.nlm.nih.gov/articles/PMC11679712/ | D9: Research paper | E9: GaN on-board charger structure | F9: 46313 | G9: High | H9: Yes | I9: Excerpt read - open and confirm | J9: =IF(I9="Opened and confirmed","Done",IF(I9="Rejected","Do not cite",IF(I9="Date to confirm","Check page date","Open link and confirm"))) -> Open link and confirm | K9: UNREACHABLE (CAPTCHA) | L9: Open manually. Title says 6.6 kW, 450 V, with integrated 1 kW 12 V converter; confirm PFC AC/DC + DC-DC stage wording.
A10: 6 | B10: Power Systems Design: SiC and GaN for EVs | C10: https://www.powersystemsdesign.com/articles/the-sic-evolution-and-gan-revolution-for-electric-vehicles/22/20881 | D10: Trade article | E10: GaN vs SiC voltage fit | F10: 46313 | G10: Medium | H10: Yes | I10: Opened and confirmed | J10: =IF(I10="Opened and confirmed","Done",IF(I10="Rejected","Do not cite",IF(I10="Date to confirm","Check page date","Open link and confirm"))) -> Done | K10: SUPPORTED | L10: Article date unclear (12/01/2023). Don't quote day/month.
A11: 7 | B11: EE Power: SiC traction inverters (ROHM) | C11: https://eepower.com/technical-articles/utilizing-sic-traction-technology-inverters-in-automotive-applications/ | D11: Trade/vendor article | E11: Size, weight, cooling example | F11: 46313 | G11: Medium (single vendor) | H11: Yes | I11: Opened and confirmed | J11: =IF(I11="Opened and confirmed","Done",IF(I11="Rejected","Do not cite",IF(I11="Date to confirm","Check page date","Open link and confirm"))) -> Done | K11: SUPPORTED | L11: Page dated 16 Jul 2018. 2,400 W is high-torque, active-switch losses only. Confirm '200 kW IGBT' comparator wording on the original page.
A12: 8 | B12: EE News Europe: ST SiC devices (2016) | C12: https://www.eenewseurope.com/en/advanced-sic-power-devices-to-accelerate-automotive-electrification/ | D12: Trade news | E12: Up to 3% efficiency claim | F12: 46313 | G12: Low (dated 2016) | H12: Yes | I12: Opened and confirmed | J12: =IF(I12="Opened and confirmed","Done",IF(I12="Rejected","Do not cite",IF(I12="Date to confirm","Check page date","Open link and confirm"))) -> Done | K12: SUPPORTED | L12: 16/17 May 2016 vendor claim, keep 'up to 3%'.
A13: 9 | B13: US DOE: Power Electronics R&D | C13: https://www.energy.gov/cmei/vehicles/power-electronics-research-and-development | D13: Government | E13: Wide-bandgap advantages (qualitative) | F13: 46313 | G13: High | H13: Yes | I13: Opened and confirmed | J13: =IF(I13="Opened and confirmed","Done",IF(I13="Rejected","Do not cite",IF(I13="Date to confirm","Check page date","Open link and confirm"))) -> Done | K13: SUPPORTED | L13: Original 2014, modified May 2026. Confirm the exact /cmei/ URL opens.
A14: 10 | B14: US DOE: 2023 Critical Materials Assessment (draft) | C14: https://www.energy.gov/sites/default/files/2023-05/2023-critical-materials-assessment.pdf | D14: Government | E14: SiC/GaN share projections; wafer bottleneck | F14: 46313 | G14: High (draft) | H14: Yes | I14: Opened and confirmed | J14: =IF(I14="Opened and confirmed","Done",IF(I14="Rejected","Do not cite",IF(I14="Date to confirm","Check page date","Open link and confirm"))) -> Done | K14: SUPPORTED | L14: Keep 'draft'. Shares are of power electronics overall; DOE cites Rosina & Villamor 2022 for them.
A15: 11 | B15: TrendForce: SiC substrate revenue 2024 | C15: https://www.trendforce.com/presscenter/news/20250512-12574.html | D15: Market research | E15: Substrate shares; oversupply | F15: 46313 | G15: High | H15: Yes | I15: Opened and confirmed | J15: =IF(I15="Opened and confirmed","Done",IF(I15="Rejected","Do not cite",IF(I15="Date to confirm","Check page date","Open link and confirm"))) -> Done | K15: SUPPORTED (via secondary report) | L15: Spell 'TanKeBlue'. Open the original TrendForce page once.
A16: 12 | B16: EE Times Asia: SiC device ranking 2023 (TrendForce) | C16: https://www.eetasia.com/trendforce-stmicroelectronics-leads-global-sic-power-device-market/ | D16: Trade news (TrendForce data) | E16: Device shares | F16: 46313 | G16: Medium | H16: Yes | I16: Opened and confirmed | J16: =IF(I16="Opened and confirmed","Done",IF(I16="Rejected","Do not cite",IF(I16="Date to confirm","Check page date","Open link and confirm"))) -> Done | K16: PARTLY | L16: Used only for onsemi/GTAT and Infineon having no in-house SiC crystal. The page does NOT give onsemi 23.6% or Infineon 16.5%; those figures were removed. Device shares now cite [38].
A17: 13 | B17: Renesas: AEC-Q101 | C17: https://renesas.com/en/products/automotive-products/aec-q101 | D17: Company | E17: AEC-Q101 definition | F17: 46313 | G17: Medium (vendor) | H17: Yes | I17: Opened and confirmed | J17: =IF(I17="Opened and confirmed","Done",IF(I17="Rejected","Do not cite",IF(I17="Date to confirm","Check page date","Open link and confirm"))) -> Done | K17: SUPPORTED | L17: No date shown.
A18: 14 | B18: PMO India: Cabinet approves three units (29 Feb 2024) | C18: https://www.pmindia.gov.in/en/news_updates/giant-leap-for-india-semiconductor-mission-cabinet-approves-three-more-semiconductor-units/ | D18: Government | E18: Tata, CG Power project details | F18: 46313 | G18: High | H18: Yes | I18: Opened and confirmed | J18: =IF(I18="Opened and confirmed","Done",IF(I18="Rejected","Do not cite",IF(I18="Date to confirm","Check page date","Open link and confirm"))) -> Done
A19: 15 | B19: India Briefing: four new plants (Aug 2025) | C19: https://www.india-briefing.com/news/india-4-new-semiconductor-plants-approved-2025-39180.html/ | D19: News/analysis | E19: SiCSem approval | F19: 46313 | G19: Medium (confirm on PIB) | H19: Yes | I19: Opened and confirmed | J19: =IF(I19="Opened and confirmed","Done",IF(I19="Rejected","Do not cite",IF(I19="Date to confirm","Check page date","Open link and confirm"))) -> Done | K19: SUPPORTED | L19: 12 Aug 2025. Write 'planned/approved' fab, not operating.
A20: 16 | B20: Rajya Sabha question 552, MeitY (7 Feb 2025) | C20: https://rsdebate.nic.in/bitstream/123456789/758379/1/PQ_267_07022025_U552_p269_p269.pdf | D20: Government | E20: OSAT investments | F20: 46313 | G20: High | H20: Yes | I20: Excerpt read - open and confirm | J20: =IF(I20="Opened and confirmed","Done",IF(I20="Rejected","Do not cite",IF(I20="Date to confirm","Check page date","Open link and confirm"))) -> Open link and confirm | K20: UNREACHABLE | L20: Open the PDF yourself and confirm Rs 7,584 crore (CG Power) and Rs 3,307 crore (Kaynes).
A21: 17 | B21: NITI Aayog: Future of India's Semiconductor Industry | C21: https://www.niti.gov.in/node/2328 | D21: Government | E21: 90-95% imports; USD 240 bn scenario | F21: 46313 | G21: High | H21: Yes | I21: Opened and confirmed | J21: =IF(I21="Opened and confirmed","Done",IF(I21="Rejected","Do not cite",IF(I21="Date to confirm","Check page date","Open link and confirm"))) -> Done
A22: 18 | B22: ThePrint on NITI Aayog roadmap | C22: https://www.theprint.in/india/indias-running-the-wrong-semiconductor-race-time-to-shift-gears-niti-aayog-offers-stark-advice/2945440/ | D22: News | E22: Self-sufficiency targets | F22: 46313 | G22: Medium | H22: Yes | I22: Opened and confirmed | J22: =IF(I22="Opened and confirmed","Done",IF(I22="Rejected","Do not cite",IF(I22="Date to confirm","Check page date","Open link and confirm"))) -> Done | K22: SUPPORTED | L22: Published 30 May 2026; roadmap released 29 May 2026. Add the date.
A23: 19 | B23: Tele.net: India semiconductor imports | C23: https://tele.net.in/?p=205919 | D23: Trade news | E23: FY25 imports USD 30.3 bn | F23: 46313 | G23: Medium | H23: No | I23: Rejected | J23: =IF(I23="Opened and confirmed","Done",IF(I23="Rejected","Do not cite",IF(I23="Date to confirm","Check page date","Open link and confirm"))) -> Do not cite | K23: NOT SUPPORTED | L23: WITHDRAWN: page has no import figures. FY25 import claim removed from the report and slides (see H22).
A24: 20 | B24: EE News Europe: Renesas holds fire on SiC | C24: https://www.eenewseurope.com/en/renesas-holds-fire-on-sic/ | D24: Trade news | E24: Oversupply and price pressure | F24: 46313 | G24: Medium | H24: Yes | I24: Opened and confirmed | J24: =IF(I24="Opened and confirmed","Done",IF(I24="Rejected","Do not cite",IF(I24="Date to confirm","Check page date","Open link and confirm"))) -> Done | K24: SUPPORTED | L24: 5 Jun 2025. Say 'temporarily suspended'; reasons also include Wolfspeed distress and Infineon/ST 200 mm capacity.
A25: 21 | B25: McKinsey: SiC wafer market uncertainty | C25: https://www.mckinsey.com/industries/semiconductors/our-insights/managing-uncertainty-in-the-silicon-carbide-wafer-market | D25: Consulting report | E25: Automotive-grade wafer supply | F25: 46313 | G25: High | H25: Yes | I25: Opened and confirmed | J25: =IF(I25="Opened and confirmed","Done",IF(I25="Rejected","Do not cite",IF(I25="Date to confirm","Check page date","Open link and confirm"))) -> Done | K25: SUPPORTED | L25: 6 Aug 2024. Say usable supply 'significantly lower' than announced capacity; no numeric limits given.
A26: 22 | B26: Argus Media: EV makers shore up SiC supply | C26: https://argusmedia.com/en/news-and-insights/latest-market-news/2212457-chip-shortage-prompts-ev-makers-to-shore-up-sic-supply | D26: News | E26: System-cost savings; China export controls | F26: 46313 | G26: Medium | H26: Yes | I26: Opened and confirmed | J26: =IF(I26="Opened and confirmed","Done",IF(I26="Rejected","Do not cite",IF(I26="Date to confirm","Check page date","Open link and confirm"))) -> Done | K26: PARTLY | L26: Page is from 2021. Used only for system-level savings. Export-control claim moved to [37].
A27: 23 | B27: EE Times Europe: SiC and GaN drive electrification | C27: https://www.eetimes.eu/?p=32125 | D27: Trade article | E27: Substrate over 50% of BOM | F27: 46313 | G27: Medium | H27: Yes | I27: Excerpt read - open and confirm | J27: =IF(I27="Opened and confirmed","Done",IF(I27="Rejected","Do not cite",IF(I27="Date to confirm","Check page date","Open link and confirm"))) -> Open link and confirm | K27: UNREACHABLE | L27: Could not open or find. Verify 'over 50% of BOM' manually or replace the source.
A28: 24 | B28: Global SMT: India may need USD 80 bn | C28: https://www.globalsmt.net/?p=104856 | D28: Trade news | E28: Imported equipment reliance; incentives | F28: 46313 | G28: Medium | H28: Yes | I28: Opened and confirmed | J28: =IF(I28="Opened and confirmed","Done",IF(I28="Rejected","Do not cite",IF(I28="Date to confirm","Check page date","Open link and confirm"))) -> Done | K28: SUPPORTED | L28: 25 Jun 2026. Attribute US$80 bn as 'industry estimate'.
A29: 25 | B29: US DOE merit review 2015: 88 kW SiC MOSFET | C29: https://www.energy.gov/eere/vehicles/articles/vehicle-technologies-office-merit-review-2015-88-kilowatt-automotive | D29: Government | E29: Qualification beyond AEC-Q101 | F29: 46313 | G29: Medium (dated 2015) | H29: Yes | I29: Opened and confirmed | J29: =IF(I29="Opened and confirmed","Done",IF(I29="Rejected","Do not cite",IF(I29="Date to confirm","Check page date","Open link and confirm"))) -> Done | K29: PARTLY | L29: Says additional qualification beyond AEC-Q101 is needed; carmakers not named. Report wording fixed.
A30: 26 | B30: Newark: SPI isolated communication in EV BMS | C30: https://www.newark.com/es/technical-resources/how-to-guide/spi-isolated-communication-helps-battery-monitoring-system-in-evs | D30: Distributor guide | E30: Isolation in BMS | F30: 46313 | G30: Medium | H30: Yes | I30: Opened and confirmed | J30: =IF(I30="Opened and confirmed","Done",IF(I30="Rejected","Do not cite",IF(I30="Date to confirm","Check page date","Open link and confirm"))) -> Done | K30: SUPPORTED | L30: Isolation sits between HV measurement circuit and LV MCU. No date shown.
A31: 27 | B31: Utmel: IATF 16949 guide | C31: https://www.utmel.com/blog/categories/semiconductor/iatf-16949-for-automotive-electronics-quality-requirements-standards-alignment-and-certification-guide | D31: Distributor blog | E31: IATF 16949 definition | F31: 46313 | G31: Medium | H31: Yes | I31: Opened and confirmed | J31: =IF(I31="Opened and confirmed","Done",IF(I31="Rejected","Do not cite",IF(I31="Date to confirm","Check page date","Open link and confirm"))) -> Done | K31: SUPPORTED | L31: Original URL blocked; hyphenated URL opened (iatf-16949). Fix URL. Dated 4 Sep 2026.
A32: 28 | B32: PM India (PIB mirror): Cabinet approves two more units (5 May 2026) | C32: https://www.pmindia.gov.in/en/news_updates/cabinet-approves-two-more-semiconductor-manufacturing-units-with-cumulative-investment-of-more-than-rs-3900-crore/ | D32: Government | E32: 12 projects; shipments; Crystal Matrix, Suchi | F32: 46314 | G32: High | H32: Yes | I32: Opened and confirmed | J32: =IF(I32="Opened and confirmed","Done",IF(I32="Rejected","Do not cite",IF(I32="Date to confirm","Check page date","Open link and confirm"))) -> Done | K32: REPLACED with official page - SUPPORTED | L32: Reference [28] updated. Old test.uniindia.com link dropped.
A33: 29 | B33: Entrepreneur India: two units approved (6 May 2026) | C33: https://india.entrepreneur.com/business-news/cabinet-approves-two-semiconductor-units-worth-inr-3900-cr-in-gujarat | D33: News | E33: INR 76,000 crore; 12 projects | F33: 46314 | G33: Medium | H33: Yes | I33: Opened and confirmed | J33: =IF(I33="Opened and confirmed","Done",IF(I33="Rejected","Do not cite",IF(I33="Date to confirm","Check page date","Open link and confirm"))) -> Done | K33: SUPPORTED | L33: 6 May 2026.
... A38: 34 | B38: Indian Infrastructure: SiCSem approval (18 Sep 2026) | C38: https://indianinfrastructure.com/2026/09/18/odisha-government-approves-building-silicon-carbide-semiconductor-plant-worth-rs-34-06-billion-near-bhubaneswar/ | D38: Trade news | E38: SiCSem product mix and output | F38: 46314 | G38: Medium | H38: Yes | I38: Opened and confirmed | J38: =IF(I38="Opened and confirmed","Done",IF(I38="Rejected","Do not cite",IF(I38="Date to confirm","Check page date","Open link and confirm"))) -> Done | K38: SUPPORTED | L38: Body says Falta SEZ committee approved; headline says Odisha govt. Use body wording.
A39: R1 | B39: Tradejini broker blog | C39: https://www.tradejini.com/blogs/inside-indias-ambitious-semiconductor-manufacturing-mission | D39: Broker blog | E39: Tata-PSMC fab details | F39: 46313 | G39: Weak; replaced by [14] | H39: No | I39: Rejected | J39: =IF(I39="Opened and confirmed","Done",IF(I39="Rejected","Do not cite",IF(I39="Date to confirm","Check page date","Open link and confirm"))) -> Do not cite
A40: R2 | B40: Adda247 exam-prep site | C40: https://currentaffairs.adda247.com/semiconductor-plants-in-india-2026-complete-list-locations-and-manufacturing-details/ | D40: Exam-prep site | E40: 12-projects claim | F40: 46313 | G40: Weak; replaced by [28][29][30] | H40: No | I40: Rejected | J40: =IF(I40="Opened and confirmed","Done",IF(I40="Rejected","Do not cite",IF(I40="Date to confirm","Check page date","Open link and confirm"))) -> Do not cite
A41: R3 | B41: Ananta IAS blog | C41: https://anantamias.com/semiconductor-mission-india/ | D41: Exam-prep blog | E41: 'Six projects' claim | F41: 46313 | G41: Unreliable; counts differ | H41: No | I41: Rejected | J41: =IF(I41="Opened and confirmed","Done",IF(I41="Rejected","Do not cite",IF(I41="Date to confirm","Check page date","Open link and confirm"))) -> Do not cite
A42: R4 | B42: PatSnap blog | C42: https://www.patsnap.com/resources/blog/articles/sic-replacing-igbt-in-ev-inverters-3-5-efficiency-gain/ | D42: Vendor blog | E42: 3-5% efficiency claim | F42: 46313 | G42: Weak; not used (see conflict C1) | H42: No | I42: Rejected | J42: =IF(I42="Opened and confirmed","Done",IF(I42="Rejected","Do not cite",IF(I42="Date to confirm","Check page date","Open link and confirm"))) -> Do not cite
A43: R5 | B43: Laoyaoba article (2023) | C43: https://laoyaoba.com/n/882015 | D43: Trade news (2023) | E43: Older SiC shares | F43: 46313 | G43: Outdated; different method | H43: No | I43: Rejected | J43: =IF(I43="Opened and confirmed","Done",IF(I43="Rejected","Do not cite",IF(I43="Date to confirm","Check page date","Open link and confirm"))) -> Do not cite
A44: R6 | B44: Digitimes SiC tag page | C44: https://www.digitimes.com/tag/sic/0118558.html | D44: Trade news (tag page) | E44: Oversupply claim | F44: 46313 | G44: No original article found | H44: No | I44: Rejected | J44: =IF(I44="Opened and confirmed","Done",IF(I44="Rejected","Do not cite",IF(I44="Date to confirm","Check page date","Open link and confirm"))) -> Do not cite
A45: R7 | B45: Coherent Market Insights page | C45: URL not given by Perplexity | D45: Market-research marketing page | E45: Taiwan concentration | F45: 46313 | G45: Marketing page; uncheckable | H45: No | I45: Rejected | J45: =IF(I45="Opened and confirmed","Done",IF(I45="Rejected","Do not cite",IF(I45="Date to confirm","Check page date","Open link and confirm"))) -> Do not cite
...

Sheet Summary
A1: Source log summary (updates automatically)
A3: Total sources logged | B3: =COUNTA(SourceLog!A5:A100) -> 48
A4: Used in report | B4: =COUNTIF(SourceLog!H5:H100,"Yes") -> 39
A5: Rejected (not used) | B5: =COUNTIF(SourceLog!H5:H100,"No") -> 9
A7: Status of used sources
A8: Opened and confirmed | B8: =COUNTIFS(SourceLog!H5:H100,"Yes",SourceLog!I5:I100,"Opened and confirmed") -> 36
A9: Excerpt read - open and confirm | B9: =COUNTIFS(SourceLog!H5:H100,"Yes",SourceLog!I5:I100,"Excerpt read - open and confirm") -> 3
A10: Date to confirm | B10: =COUNTIFS(SourceLog!H5:H100,"Yes",SourceLog!I5:I100,"Date to confirm") -> 0
A12: Used sources opened and confirmed (%) | B12: =IFERROR(B8/B4,0) -> 0.92307692
A13: Open actions still to do | B13: =COUNTIF(SourceLog!J5:J100,"Open link and confirm")+COUNTIF(SourceLog!J5:J100,"Check page date") -> 3
A15: Used sources by type
A16: Government | B16: =COUNTIFS(SourceLog!H5:H100,"Yes",SourceLog!D5:D100,"Government") -> 9
A17: Research paper | B17: =COUNTIFS(SourceLog!H5:H100,"Yes",SourceLog!D5:D100,"Research paper") -> 2
A18: Market research / consulting | B18: =COUNTIFS(SourceLog!H5:H100,"Yes",SourceLog!D5:D100,"Market research")+COUNTIFS(SourceLog!H5:H100,"Yes",SourceLog!D5:D100,"Consulting report") -> 3
A19: Company | B19: =COUNTIFS(SourceLog!H5:H100,"Yes",SourceLog!D5:D100,"Company") -> 5
A21: Note: 'Opened and confirmed' means the full page was opened and read. Others were read as search excerpts; open them before submission.

Sheet HowItWorks
A1: How the automation works
A2: 1. Each source gets one row: ID, URL, type, claim supported, date accessed, trust level.
A3: 2. Pick the verification status from the drop-down (column I). Column J (Open action) updates by formula.
A4: 3. The Summary sheet counts statuses and types with COUNTIF/COUNTIFS, so it needs no manual totals.
A5: 4. Colour rules: green = done, yellow = still to open or check the date, red = do not cite.
A6: 5. Optional extension: connect a Google Form to a Google Sheet (or a Zapier/Make flow) so each submitted URL adds a row with today's date and status 'Excerpt read - open and confirm'.
A7: 6. Before submission: filter column J for 'Open link and confirm' and 'Check page date' and clear every row.
A8: Sources: ID numbers 1-34 match the reference numbers in the research report; R1-R8 are rejected sources.
A9: Update 24 Oct 2026: columns K-L added from a re-check of all 34 used sources. Statuses are Opened and confirmed where the page text was read. [5], [16], [23] could not be opened in the final check and stay flagged; [19] is withdrawn.
